<robot name="butler_robot">

  <!-- Base Link (Main body of the robot) -->
  <link name="base_link">
    <visual>
      <geometry>
        <box size="0.4 0.4 0.2"/> <!-- Length, Width, Height -->
      </geometry>
      <material name="yellow">
        <color rgba="1 1 0 1"/>
      </material>
    </visual>
    <collision>
      <geometry>
        <box size="0.4 0.4 0.2"/>
      </geometry>
    </collision>
    <inertial>
      <mass value="1.0"/>
      <inertia ixx="0.1" iyy="0.1" izz="0.1" ixy="0.0" ixz="0.0" iyz="0.0"/>
    </inertial>
  </link>

  <!-- Left Wheel -->
  <link name="left_wheel"/>

  <!-- Right Wheel -->
  <link name="right_wheel"/>

  <!-- Left Wheel Joint -->
  <joint name="left_wheel_joint" type="continuous">
    <parent link="base_link"/>
    <child link="left_wheel"/>
    <axis xyz="0 1 0"/>
    <origin xyz="0 -0.15 0"/>
  </joint>

  <!-- Right Wheel Joint -->
  <joint name="right_wheel_joint" type="continuous">
    <parent link="base_link"/>
    <child link="right_wheel"/>
    <axis xyz="0 1 0"/>
    <origin xyz="0 0.15 0"/>
  </joint>

  <!-- Differential Drive Plugin (Gazebo Control Plugin) -->
  <gazebo>
    <plugin name="differential_drive_controller" filename="libgazebo_ros_diff_drive.so">
      <robotNamespace>/butler_robot</robotNamespace>
      <commandTopic>cmd_vel</commandTopic>
      <odometryTopic>odom</odometryTopic>
      <leftJoint>left_wheel_joint</leftJoint>
      <rightJoint>right_wheel_joint</rightJoint>
      <wheelSeparation>0.3</wheelSeparation>
      <wheelDiameter>0.1</wheelDiameter>
      <updateRate>50</updateRate>
    </plugin>
  </gazebo>

</robot>

